Traceback (most recent call last):
  File "/Users/m0n/opt/anaconda3/lib/python3.9/site-packages/jupyter_cache/executors/utils.py", line 51, in single_nb_execution
    executenb(
  File "/Users/m0n/opt/anaconda3/lib/python3.9/site-packages/nbclient/client.py", line 1204, in execute
    return NotebookClient(nb=nb, resources=resources, km=km, **kwargs).execute()
  File "/Users/m0n/opt/anaconda3/lib/python3.9/site-packages/nbclient/util.py", line 84, in wrapped
    return just_run(coro(*args, **kwargs))
  File "/Users/m0n/opt/anaconda3/lib/python3.9/site-packages/nbclient/util.py", line 62, in just_run
    return loop.run_until_complete(coro)
  File "/Users/m0n/opt/anaconda3/lib/python3.9/asyncio/base_events.py", line 647, in run_until_complete
    return future.result()
  File "/Users/m0n/opt/anaconda3/lib/python3.9/site-packages/nbclient/client.py", line 663, in async_execute
    await self.async_execute_cell(
  File "/Users/m0n/opt/anaconda3/lib/python3.9/site-packages/nbclient/client.py", line 965, in async_execute_cell
    await self._check_raise_for_error(cell, cell_index, exec_reply)
  File "/Users/m0n/opt/anaconda3/lib/python3.9/site-packages/nbclient/client.py", line 862, in _check_raise_for_error
    raise CellExecutionError.from_cell_and_msg(cell, exec_reply_content)
nbclient.exceptions.CellExecutionError: An error occurred while executing the following cell:
------------------
import pandas as pd
from zipminator import Zipndel

df = pd.DataFrame({'A': [1, 2, 3], 'B': [4, 5, 6], 'C': [7, 8, 9]})
Zipndel(file_name='my_file', password='my_password', mask_columns=['B'], anonymize_columns=['C']).zipit(df)
------------------

[0;31m---------------------------------------------------------------------------[0m
[0;31mTypeError[0m                                 Traceback (most recent call last)
Cell [0;32mIn[1], line 5[0m
[1;32m      2[0m [38;5;28;01mfrom[39;00m [38;5;21;01mzipminator[39;00m [38;5;28;01mimport[39;00m Zipndel
[1;32m      4[0m df [38;5;241m=[39m pd[38;5;241m.[39mDataFrame({[38;5;124m'[39m[38;5;124mA[39m[38;5;124m'[39m: [[38;5;241m1[39m, [38;5;241m2[39m, [38;5;241m3[39m], [38;5;124m'[39m[38;5;124mB[39m[38;5;124m'[39m: [[38;5;241m4[39m, [38;5;241m5[39m, [38;5;241m6[39m], [38;5;124m'[39m[38;5;124mC[39m[38;5;124m'[39m: [[38;5;241m7[39m, [38;5;241m8[39m, [38;5;241m9[39m]})
[0;32m----> 5[0m [43mZipndel[49m[43m([49m[43mfile_name[49m[38;5;241;43m=[39;49m[38;5;124;43m'[39;49m[38;5;124;43mmy_file[39;49m[38;5;124;43m'[39;49m[43m,[49m[43m [49m[43mpassword[49m[38;5;241;43m=[39;49m[38;5;124;43m'[39;49m[38;5;124;43mmy_password[39;49m[38;5;124;43m'[39;49m[43m,[49m[43m [49m[43mmask_columns[49m[38;5;241;43m=[39;49m[43m[[49m[38;5;124;43m'[39;49m[38;5;124;43mB[39;49m[38;5;124;43m'[39;49m[43m][49m[43m,[49m[43m [49m[43manonymize_columns[49m[38;5;241;43m=[39;49m[43m[[49m[38;5;124;43m'[39;49m[38;5;124;43mC[39;49m[38;5;124;43m'[39;49m[43m][49m[43m)[49m[38;5;241m.[39mzipit(df)

[0;31mTypeError[0m: __init__() got an unexpected keyword argument 'password'
TypeError: __init__() got an unexpected keyword argument 'password'

